<?xml version="1.0" encoding="utf-8"?>
<!-- =================================================================================== -->
<!-- |    This document was autogenerated by xacro from dorna.urdf.xacro               | -->
<!-- |    EDITING THIS FILE BY HAND IS NOT RECOMMENDED                                 | -->
<!-- =================================================================================== -->
<robot name="dorna" xmlns:xacro="http://ros.org/wiki/xacro">
  <link name="world">
    </link>
  <!-- scale the .STL to the right dim -->
  <!-- <xacro:property name="transmission_type" value="${transmission_type}" /> -->
  <!-- [rad/sec] -->
  <!-- [%] -->
  <!-- [rad/sec] -->
  <!-- [%] -->
  <!-- [rad/sec] -->
  <!-- [%] -->
  <!-- ros_control plugin -->
  <gazebo>
    <plugin filename="libgazebo_ros_control.so" name="gazebo_ros_control">
      <robotNamespace>/dorna</robotNamespace>
      <robotSimType>gazebo_ros_control/DefaultRobotHWSim</robotSimType>
    </plugin>
  </gazebo>
  <!-- Base -->
  <gazebo reference="dorna_base">
    <material>Gazebo/Orange</material>
  </gazebo>
  <gazebo reference="dorna_arm_0">
    <mu1>0.2</mu1>
    <mu2>0.2</mu2>
    <material>Gazebo/Black</material>
  </gazebo>
  <gazebo reference="dorna_arm_1">
    <mu1>0.2</mu1>
    <mu2>0.2</mu2>
    <material>Gazebo/Orange</material>
  </gazebo>
  <gazebo reference="dorna_arm_2">
    <mu1>0.2</mu1>
    <mu2>0.2</mu2>
    <material>Gazebo/Red</material>
  </gazebo>
  <gazebo reference="dorna_arm_3">
    <mu1>0.2</mu1>
    <mu2>0.2</mu2>
    <material>Gazebo/Orange</material>
  </gazebo>
  <gazebo reference="dorna_arm_4">
    <mu1>0.2</mu1>
    <mu2>0.2</mu2>
    <material>Gazebo/Black</material>
  </gazebo>
  <gazebo reference="dorna_end_effector">
    <mu1>0.2</mu1>
    <mu2>0.2</mu2>
    <material>Gazebo/Blue</material>
  </gazebo>
  <material name="black">
    <color rgba="0.0 0.0 0.0 1.0"/>
  </material>
  <material name="blue">
    <color rgba="0.0 0.0 0.8 1.0"/>
  </material>
  <material name="green">
    <color rgba="0.0 0.8 0.0 1.0"/>
  </material>
  <material name="grey">
    <color rgba="0.2 0.2 0.2 1.0"/>
  </material>
  <material name="orange">
    <color rgba="1.0 0.423529411765 0.0392156862745 1.0"/>
  </material>
  <material name="brown">
    <color rgba="0.870588235294 0.811764705882 0.764705882353 1.0"/>
  </material>
  <material name="red">
    <color rgba="0.8 0.0 0.0 1.0"/>
  </material>
  <material name="white">
    <color rgba="1.0 1.0 1.0 1.0"/>
  </material>
  <!-- ########################################### -->
  <!-- Used for fixing robot to Gazebo 'base_link' -->
  <!-- ########################################### -->
  <!-- <link name="world"/> -->
  <!-- ######################### -->
  <!-- dorna_base Joint and Link -->
  <!-- ######################### -->
  <joint name="fixed" type="fixed">
    <parent link="world"/>
    <child link="dorna_base"/>
    <origin rpy="0 0 0" xyz="0 0 0"/>
    <!-- <xacro:insert_block name = "dorna_base_origin"/> -->
  </joint>
  <link name="dorna_base">
    <collision>
      <origin rpy="0 0 0" xyz="0 0 0"/>
      <geometry>
        <mesh filename="package://dorna_description/meshes/base_v8.stl" scale="0.01 0.01 0.01"/>
      </geometry>
    </collision>
    <visual>
      <origin rpy="0 0 0" xyz="0 0 0"/>
      <geometry>
        <mesh filename="package://dorna_description/meshes/base_v8.stl" scale="0.01 0.01 0.01"/>
      </geometry>
      <material name="black"/>
    </visual>
    <inertial>
      <origin rpy="0 0 0" xyz="0 0 0"/>
      <mass value="0.848"/>
      <inertia ixx="2.569" ixy="0.001" ixz="0.089" iyy="2.510" iyz="0.002" izz="1.261"/>
    </inertial>
  </link>
  <!-- ########################## -->
  <!-- dorna_arm_0 Joint and Link -->
  <!-- ########################## -->
  <joint name="dorna_base_to_dorna_arm_0" type="revolute">
    <parent link="dorna_base"/>
    <child link="dorna_arm_0"/>
    <origin rpy="0 0 0" xyz="0 0 0"/>
    <axis xyz="0 0 1"/>
    <limit effort="50" lower="-3.49" upper="3.05433" velocity="5.236"/>
    <!-- -175 deg, 175 deg -->
    <!-- <safety_controller k_velocity="10" k_position="15" soft_lower_limit="-2.88" soft_upper_limit="2.88" /> 10 degree saftey factor -->
  </joint>
  <link name="dorna_arm_0">
    <collision>
      <origin rpy="0 0 0" xyz="0.095 0 0.20603"/>
      <geometry>
        <mesh filename="package://dorna_description/meshes/j0_c.stl" scale="0.01 0.01 0.01"/>
      </geometry>
    </collision>
    <visual>
      <origin rpy="0 0 0" xyz="0.095 0 0.20603"/>
      <geometry>
        <mesh filename="package://dorna_description/meshes/j0_c.stl" scale="0.01 0.01 0.01"/>
      </geometry>
      <material name="orange"/>
    </visual>
    <inertial>
      <origin rpy="0 0 0" xyz="0 0 0"/>
      <mass value="1.579"/>
      <inertia ixx="28.253" ixy="0.0" ixz="-22.783" iyy="53.228" iyz="0.0" izz="34.568"/>
    </inertial>
  </link>
  <!-- ########################## -->
  <!-- dorna_arm_1 Joint and Link -->
  <!-- ########################## -->
  <joint name="dorna_arm_0_to_dorna_arm_1" type="revolute">
    <parent link="dorna_arm_0"/>
    <child link="dorna_arm_1"/>
    <origin rpy="3.14159265359 0 0" xyz="0.095 0 0.20603"/>
    <axis xyz="0 1 0"/>
    <limit effort="50" lower="-3.05433" upper="2.79253" velocity="2.618"/>
    <!-- -175 deg, 160 deg -->
    <!-- <safety_controller k_velocity="10" k_position="15" soft_lower_limit="-1.5" soft_upper_limit="2.52" /> 10 degree saftey factor -->
  </joint>
  <link name="dorna_arm_1">
    <collision>
      <origin rpy="0 0 0" xyz="0.20327 0 0"/>
      <geometry>
        <mesh filename="package://dorna_description/meshes/j1_c.stl" scale="0.01 0.01 0.01"/>
      </geometry>
    </collision>
    <visual>
      <origin rpy="0 0 0" xyz="0.20327 0 0"/>
      <geometry>
        <mesh filename="package://dorna_description/meshes/j1_c.stl" scale="0.01 0.01 0.01"/>
      </geometry>
      <material name="orange"/>
    </visual>
    <inertial>
      <origin rpy="0 0 0" xyz="0 0 0"/>
      <mass value="0.709"/>
      <inertia ixx="1.049" ixy="0.0" ixz="0.0" iyy="7.829" iyz="0.0" izz="8.685"/>
    </inertial>
  </link>
  <!-- ########################## -->
  <!-- dorna_arm_2 Joint and Link -->
  <!-- ########################## -->
  <joint name="dorna_arm_1_to_dorna_arm_2" type="revolute">
    <parent link="dorna_arm_1"/>
    <child link="dorna_arm_2"/>
    <origin rpy="0 0 0" xyz="0.20327 0 0"/>
    <axis xyz="0 1 0"/>
    <limit effort="50" lower="-2.26893" upper="2.26893" velocity="2.618"/>
    <!-- -130 deg, 130 deg -->
    <!-- <safety_controller k_velocity="10" k_position="15" soft_lower_limit="-2.1" soft_upper_limit="2.1" /> 10 degree saftey factor -->
  </joint>
  <link name="dorna_arm_2">
    <collision>
      <origin rpy="0 0 0" xyz="0.15245 0 0"/>
      <geometry>
        <mesh filename="package://dorna_description/meshes/j2_c.stl" scale="0.01 0.01 0.01"/>
      </geometry>
    </collision>
    <visual>
      <origin rpy="0 0 0" xyz="0.15245 0 0"/>
      <geometry>
        <mesh filename="package://dorna_description/meshes/j2_c.stl" scale="0.01 0.01 0.01"/>
      </geometry>
      <material name="orange"/>
    </visual>
    <inertial>
      <origin rpy="0 0 0" xyz="0 0 0"/>
      <mass value="0.501"/>
      <inertia ixx="1.467" ixy="0.0" ixz="0.0" iyy="10.271" iyz="0.0" izz="11.492"/>
    </inertial>
  </link>
  <!-- ########################## -->
  <!-- dorna_arm_3 Joint and Link -->
  <!-- ########################## -->
  <joint name="dorna_arm_2_to_dorna_arm_3" type="continuous">
    <parent link="dorna_arm_2"/>
    <child link="dorna_arm_3"/>
    <origin rpy="0 0 0" xyz="0.15245 0 0"/>
    <axis xyz="0 1 0"/>
    <limit effort="50" lower="0" upper="6.28318530718" velocity="5.236"/>
  </joint>
  <link name="dorna_arm_3">
    <collision>
      <origin rpy="0 0 0" xyz="0 0 0"/>
      <geometry>
        <mesh filename="package://dorna_description/meshes/j3_c.stl" scale="0.01 0.01 0.01"/>
      </geometry>
    </collision>
    <visual>
      <origin rpy="0 0 0" xyz="0 0 0"/>
      <geometry>
        <mesh filename="package://dorna_description/meshes/j3_c.stl" scale="0.01 0.01 0.01"/>
      </geometry>
      <material name="red"/>
    </visual>
    <inertial>
      <origin rpy="0 0 0" xyz="0 0 0"/>
      <mass value="0.075"/>
      <inertia ixx="0.03" ixy="0.0" ixz="0.0" iyy="0.023" iyz="0.0" izz="0.049"/>
    </inertial>
  </link>
  <!-- ########################## -->
  <!-- dorna_arm_4 Joint and Link -->
  <!-- ########################## -->
  <joint name="dorna_arm_3_to_dorna_arm_4" type="continuous">
    <parent link="dorna_arm_3"/>
    <child link="dorna_arm_4"/>
    <origin rpy="0 0 0" xyz="0.0 0.0 0.0"/>
    <axis xyz="1 0 0"/>
    <limit effort="50" lower="0" upper="6.28318530718" velocity="5.236"/>
  </joint>
  <link name="dorna_arm_4">
    <collision>
      <origin rpy="0 0 0" xyz="0 0 0"/>
      <geometry>
        <mesh filename="package://dorna_description/meshes/j4_c.stl" scale="0.01 0.01 0.01"/>
      </geometry>
    </collision>
    <visual>
      <origin rpy="0 0 0" xyz="0 0 0"/>
      <geometry>
        <mesh filename="package://dorna_description/meshes/j4_c.stl" scale="0.01 0.01 0.01"/>
      </geometry>
      <material name="red"/>
    </visual>
    <inertial>
      <origin rpy="0 0 0" xyz="0 0 0"/>
      <mass value="0.042"/>
      <inertia ixx="0.002" ixy="0.0" ixz="0.0" iyy="0.044" iyz="0.0" izz="0.044"/>
    </inertial>
  </link>
  <!-- ########################## -->
  <!-- dorna_end_effector Joint and Link -->
  <!-- ########################## -->
  <joint name="dorna_arm_4_to_dorna_end_effector" type="fixed">
    <parent link="dorna_arm_4"/>
    <child link="dorna_end_effector"/>
    <origin rpy="0 -1.57079632679 1.57079632679" xyz="0.0315 0.0 0.0"/>
  </joint>
  <link name="dorna_end_effector">
    <collision>
      <origin rpy="0 0 0" xyz="0 0 0"/>
      <geometry>
        <mesh filename="package://dorna_description/meshes/one_finger_asm.stl" scale="0.001 0.001 0.001"/>
        <!-- <mesh filename="package://dorna_description/meshes/1_finger_tool.stl" scale="${0.001} ${0.001} ${0.001}"/> -->
      </geometry>
    </collision>
    <visual>
      <origin rpy="0 0 0" xyz="0 0 0"/>
      <geometry>
        <mesh filename="package://dorna_description/meshes/one_finger_asm.stl" scale="0.001 0.001 0.001"/>
        <!-- <mesh filename="package://dorna_description/meshes/1_finger_tool.stl" scale="${0.001} ${0.001} ${0.001}"/> -->
      </geometry>
      <material name="blue"/>
    </visual>
    <inertial>
      <origin rpy="0 0 0" xyz="0 0 0"/>
      <mass value="0.042"/>
      <inertia ixx="0.002" ixy="0.0" ixz="0.0" iyy="0.044" iyz="0.0" izz="0.044"/>
    </inertial>
  </link>
  <link name="finger_tip">
    </link>
  <joint name="dorna_end_effector_to_finger_tip" type="fixed">
    <parent link="dorna_end_effector"/>
    <child link="finger_tip"/>
    <origin rpy="1.57079632679 0 -1.57079632679" xyz="0 -0.102 0"/>
  </joint>
  <link name="pump">
    </link>
  <joint name="dorna_end_effector_to_pump" type="fixed">
    <parent link="dorna_end_effector"/>
    <child link="pump"/>
    <origin rpy="0 0 0" xyz="0.09 -0.045 0"/>
  </joint>
  <transmission name="tran0_pos">
    <type>transmission_interface/SimpleTransmission</type>
    <joint name="dorna_base_to_dorna_arm_0">
      <hardwareInterface>hardware_interface/PositionJointInterface</hardwareInterface>
    </joint>
    <actuator name="motor0_pos">
      <hardwareInterface>hardware_interface/PositionJointInterface</hardwareInterface>
      <mechanicalReduction>1</mechanicalReduction>
    </actuator>
  </transmission>
  <transmission name="tran1_pos">
    <type>transmission_interface/SimpleTransmission</type>
    <joint name="dorna_arm_0_to_dorna_arm_1">
      <hardwareInterface>hardware_interface/PositionJointInterface</hardwareInterface>
    </joint>
    <actuator name="motor1_pos">
      <hardwareInterface>hardware_interface/PositionJointInterface</hardwareInterface>
      <mechanicalReduction>1</mechanicalReduction>
    </actuator>
  </transmission>
  <transmission name="tran2_pos">
    <type>transmission_interface/SimpleTransmission</type>
    <joint name="dorna_arm_1_to_dorna_arm_2">
      <hardwareInterface>hardware_interface/PositionJointInterface</hardwareInterface>
    </joint>
    <actuator name="motor2_pos">
      <hardwareInterface>hardware_interface/PositionJointInterface</hardwareInterface>
      <mechanicalReduction>1</mechanicalReduction>
    </actuator>
  </transmission>
  <transmission name="tran3_pos">
    <type>transmission_interface/SimpleTransmission</type>
    <joint name="dorna_arm_2_to_dorna_arm_3">
      <hardwareInterface>hardware_interface/PositionJointInterface</hardwareInterface>
    </joint>
    <actuator name="motor3_pos">
      <hardwareInterface>hardware_interface/PositionJointInterface</hardwareInterface>
      <mechanicalReduction>1</mechanicalReduction>
    </actuator>
  </transmission>
  <transmission name="tran4_pos">
    <type>transmission_interface/SimpleTransmission</type>
    <joint name="dorna_arm_3_to_dorna_arm_4">
      <hardwareInterface>hardware_interface/PositionJointInterface</hardwareInterface>
    </joint>
    <actuator name="motor4_pos">
      <hardwareInterface>hardware_interface/PositionJointInterface</hardwareInterface>
      <mechanicalReduction>1</mechanicalReduction>
    </actuator>
  </transmission>
  <!-- ############# -->
  <!-- gazebo static -->
  <!-- ############# -->
  <gazebo>
    <static>false</static>
  </gazebo>
</robot>

